[{"url":"https://api.github.com/repos/pycaret/pycaret/issues/571","repository_url":"https://api.github.com/repos/pycaret/pycaret","labels_url":"https://api.github.com/repos/pycaret/pycaret/issues/571/labels{/name}","comments_url":"https://api.github.com/repos/pycaret/pycaret/issues/571/comments","events_url":"https://api.github.com/repos/pycaret/pycaret/issues/571/events","html_url":"https://github.com/pycaret/pycaret/issues/571","id":688766564,"node_id":"MDU6SXNzdWU2ODg3NjY1NjQ=","number":571,"title":"Facing issue when load .pkl in new environment , NameError: name 'target_inverse_transformer' is not defined","user":{"login":"saitej123","id":18657211,"node_id":"MDQ6VXNlcjE4NjU3MjEx","avatar_url":"https://avatars3.githubusercontent.com/u/18657211?v=4","gravatar_id":"","url":"https://api.github.com/users/saitej123","html_url":"https://github.com/saitej123","followers_url":"https://api.github.com/users/saitej123/followers","following_url":"https://api.github.com/users/saitej123/following{/other_user}","gists_url":"https://api.github.com/users/saitej123/gists{/gist_id}","starred_url":"https://api.github.com/users/saitej123/starred{/owner}{/repo}","subscriptions_url":"https://api.github.com/users/saitej123/subscriptions","organizations_url":"https://api.github.com/users/saitej123/orgs","repos_url":"https://api.github.com/users/saitej123/repos","events_url":"https://api.github.com/users/saitej123/events{/privacy}","received_events_url":"https://api.github.com/users/saitej123/received_events","type":"User","site_admin":false},"labels":[{"id":1694165746,"node_id":"MDU6TGFiZWwxNjk0MTY1NzQ2","url":"https://api.github.com/repos/pycaret/pycaret/labels/bug","name":"bug","color":"d73a4a","default":true,"description":"Something isn't working"},{"id":1694165751,"node_id":"MDU6TGFiZWwxNjk0MTY1NzUx","url":"https://api.github.com/repos/pycaret/pycaret/labels/duplicate","name":"duplicate","color":"cfd3d7","default":true,"description":"This issue or pull request already exists"}],"state":"closed","locked":false,"assignee":{"login":"pycaret","id":58118658,"node_id":"MDQ6VXNlcjU4MTE4NjU4","avatar_url":"https://avatars1.githubusercontent.com/u/58118658?v=4","gravatar_id":"","url":"https://api.github.com/users/pycaret","html_url":"https://github.com/pycaret","followers_url":"https://api.github.com/users/pycaret/followers","following_url":"https://api.github.com/users/pycaret/following{/other_user}","gists_url":"https://api.github.com/users/pycaret/gists{/gist_id}","starred_url":"https://api.github.com/users/pycaret/starred{/owner}{/repo}","subscriptions_url":"https://api.github.com/users/pycaret/subscriptions","organizations_url":"https://api.github.com/users/pycaret/orgs","repos_url":"https://api.github.com/users/pycaret/repos","events_url":"https://api.github.com/users/pycaret/events{/privacy}","received_events_url":"https://api.github.com/users/pycaret/received_events","type":"User","site_admin":false},"assignees":[{"login":"pycaret","id":58118658,"node_id":"MDQ6VXNlcjU4MTE4NjU4","avatar_url":"https://avatars1.githubusercontent.com/u/58118658?v=4","gravatar_id":"","url":"https://api.github.com/users/pycaret","html_url":"https://github.com/pycaret","followers_url":"https://api.github.com/users/pycaret/followers","following_url":"https://api.github.com/users/pycaret/following{/other_user}","gists_url":"https://api.github.com/users/pycaret/gists{/gist_id}","starred_url":"https://api.github.com/users/pycaret/starred{/owner}{/repo}","subscriptions_url":"https://api.github.com/users/pycaret/subscriptions","organizations_url":"https://api.github.com/users/pycaret/orgs","repos_url":"https://api.github.com/users/pycaret/repos","events_url":"https://api.github.com/users/pycaret/events{/privacy}","received_events_url":"https://api.github.com/users/pycaret/received_events","type":"User","site_admin":false}],"milestone":null,"comments":8,"created_at":"2020-08-30T18:20:40Z","updated_at":"2020-08-31T16:55:46Z","closed_at":"2020-08-31T16:53:15Z","author_association":"NONE","active_lock_reason":null,"body":"For my streamlit app , used only .pkl output from pycaret. when I loaded and run the app, got error\r\n\r\nname 'target_inverse_transformer' is not defined. 2 months back I used same code It was working .\r\n\r\nbut when I loaded the pkl file in the  same notebook where I created model, it is fine . \r\n\r\n![image](https://user-images.githubusercontent.com/18657211/91666585-984c4100-eb1b-11ea-9a9a-a4cd78f754fd.png)\r\n","performed_via_github_app":null},{"url":"https://api.github.com/repos/pycaret/pycaret/issues/566","repository_url":"https://api.github.com/repos/pycaret/pycaret","labels_url":"https://api.github.com/repos/pycaret/pycaret/issues/566/labels{/name}","comments_url":"https://api.github.com/repos/pycaret/pycaret/issues/566/comments","events_url":"https://api.github.com/repos/pycaret/pycaret/issues/566/events","html_url":"https://github.com/pycaret/pycaret/issues/566","id":688562429,"node_id":"MDU6SXNzdWU2ODg1NjI0Mjk=","number":566,"title":"Compare models MLFlowException","user":{"login":"sagarnildass","id":18384685,"node_id":"MDQ6VXNlcjE4Mzg0Njg1","avatar_url":"https://avatars0.githubusercontent.com/u/18384685?v=4","gravatar_id":"","url":"https://api.github.com/users/sagarnildass","html_url":"https://github.com/sagarnildass","followers_url":"https://api.github.com/users/sagarnildass/followers","following_url":"https://api.github.com/users/sagarnildass/following{/other_user}","gists_url":"https://api.github.com/users/sagarnildass/gists{/gist_id}","starred_url":"https://api.github.com/users/sagarnildass/starred{/owner}{/repo}","subscriptions_url":"https://api.github.com/users/sagarnildass/subscriptions","organizations_url":"https://api.github.com/users/sagarnildass/orgs","repos_url":"https://api.github.com/users/sagarnildass/repos","events_url":"https://api.github.com/users/sagarnildass/events{/privacy}","received_events_url":"https://api.github.com/users/sagarnildass/received_events","type":"User","site_admin":false},"labels":[{"id":1694165746,"node_id":"MDU6TGFiZWwxNjk0MTY1NzQ2","url":"https://api.github.com/repos/pycaret/pycaret/labels/bug","name":"bug","color":"d73a4a","default":true,"description":"Something isn't working"}],"state":"closed","locked":false,"assignee":{"login":"Yard1","id":10364161,"node_id":"MDQ6VXNlcjEwMzY0MTYx","avatar_url":"https://avatars1.githubusercontent.com/u/10364161?v=4","gravatar_id":"","url":"https://api.github.com/users/Yard1","html_url":"https://github.com/Yard1","followers_url":"https://api.github.com/users/Yard1/followers","following_url":"https://api.github.com/users/Yard1/following{/other_user}","gists_url":"https://api.github.com/users/Yard1/gists{/gist_id}","starred_url":"https://api.github.com/users/Yard1/starred{/owner}{/repo}","subscriptions_url":"https://api.github.com/users/Yard1/subscriptions","organizations_url":"https://api.github.com/users/Yard1/orgs","repos_url":"https://api.github.com/users/Yard1/repos","events_url":"https://api.github.com/users/Yard1/events{/privacy}","received_events_url":"https://api.github.com/users/Yard1/received_events","type":"User","site_admin":false},"assignees":[{"login":"Yard1","id":10364161,"node_id":"MDQ6VXNlcjEwMzY0MTYx","avatar_url":"https://avatars1.githubusercontent.com/u/10364161?v=4","gravatar_id":"","url":"https://api.github.com/users/Yard1","html_url":"https://github.com/Yard1","followers_url":"https://api.github.com/users/Yard1/followers","following_url":"https://api.github.com/users/Yard1/following{/other_user}","gists_url":"https://api.github.com/users/Yard1/gists{/gist_id}","starred_url":"https://api.github.com/users/Yard1/starred{/owner}{/repo}","subscriptions_url":"https://api.github.com/users/Yard1/subscriptions","organizations_url":"https://api.github.com/users/Yard1/orgs","repos_url":"https://api.github.com/users/Yard1/repos","events_url":"https://api.github.com/users/Yard1/events{/privacy}","received_events_url":"https://api.github.com/users/Yard1/received_events","type":"User","site_admin":false},{"login":"sagarnildass","id":18384685,"node_id":"MDQ6VXNlcjE4Mzg0Njg1","avatar_url":"https://avatars0.githubusercontent.com/u/18384685?v=4","gravatar_id":"","url":"https://api.github.com/users/sagarnildass","html_url":"https://github.com/sagarnildass","followers_url":"https://api.github.com/users/sagarnildass/followers","following_url":"https://api.github.com/users/sagarnildass/following{/other_user}","gists_url":"https://api.github.com/users/sagarnildass/gists{/gist_id}","starred_url":"https://api.github.com/users/sagarnildass/starred{/owner}{/repo}","subscriptions_url":"https://api.github.com/users/sagarnildass/subscriptions","organizations_url":"https://api.github.com/users/sagarnildass/orgs","repos_url":"https://api.github.com/users/sagarnildass/repos","events_url":"https://api.github.com/users/sagarnildass/events{/privacy}","received_events_url":"https://api.github.com/users/sagarnildass/received_events","type":"User","site_admin":false},{"login":"moezali1","id":54699234,"node_id":"MDQ6VXNlcjU0Njk5MjM0","avatar_url":"https://avatars2.githubusercontent.com/u/54699234?v=4","gravatar_id":"","url":"https://api.github.com/users/moezali1","html_url":"https://github.com/moezali1","followers_url":"https://api.github.com/users/moezali1/followers","following_url":"https://api.github.com/users/moezali1/following{/other_user}","gists_url":"https://api.github.com/users/moezali1/gists{/gist_id}","starred_url":"https://api.github.com/users/moezali1/starred{/owner}{/repo}","subscriptions_url":"https://api.github.com/users/moezali1/subscriptions","organizations_url":"https://api.github.com/users/moezali1/orgs","repos_url":"https://api.github.com/users/moezali1/repos","events_url":"https://api.github.com/users/moezali1/events{/privacy}","received_events_url":"https://api.github.com/users/moezali1/received_events","type":"User","site_admin":false},{"login":"pycaret","id":58118658,"node_id":"MDQ6VXNlcjU4MTE4NjU4","avatar_url":"https://avatars1.githubusercontent.com/u/58118658?v=4","gravatar_id":"","url":"https://api.github.com/users/pycaret","html_url":"https://github.com/pycaret","followers_url":"https://api.github.com/users/pycaret/followers","following_url":"https://api.github.com/users/pycaret/following{/other_user}","gists_url":"https://api.github.com/users/pycaret/gists{/gist_id}","starred_url":"https://api.github.com/users/pycaret/starred{/owner}{/repo}","subscriptions_url":"https://api.github.com/users/pycaret/subscriptions","organizations_url":"https://api.github.com/users/pycaret/orgs","repos_url":"https://api.github.com/users/pycaret/repos","events_url":"https://api.github.com/users/pycaret/events{/privacy}","received_events_url":"https://api.github.com/users/pycaret/received_events","type":"User","site_admin":false}],"milestone":null,"comments":9,"created_at":"2020-08-29T16:24:24Z","updated_at":"2020-08-30T16:57:34Z","closed_at":"2020-08-30T16:57:33Z","author_association":"NONE","active_lock_reason":null,"body":"Hi. I just upgraded to pycaret 2.1. When I ran the compare_models function with the Titanic dataset, I got the following error:\r\n\r\nMlflowException: Unable to map 'np.object' type to MLflow DataType. np.object canbe mapped iff all values have identical data type which is one of (string, (bytes or byterray),  int, float)\r\n\r\nThe same code worked fine in pycaret 2.0.","performed_via_github_app":null},{"url":"https://api.github.com/repos/pycaret/pycaret/issues/525","repository_url":"https://api.github.com/repos/pycaret/pycaret","labels_url":"https://api.github.com/repos/pycaret/pycaret/issues/525/labels{/name}","comments_url":"https://api.github.com/repos/pycaret/pycaret/issues/525/comments","events_url":"https://api.github.com/repos/pycaret/pycaret/issues/525/events","html_url":"https://github.com/pycaret/pycaret/issues/525","id":684464307,"node_id":"MDU6SXNzdWU2ODQ0NjQzMDc=","number":525,"title":"Prediction with Saved Model Attribute Error","user":{"login":"Wookloo","id":36540215,"node_id":"MDQ6VXNlcjM2NTQwMjE1","avatar_url":"https://avatars3.githubusercontent.com/u/36540215?v=4","gravatar_id":"","url":"https://api.github.com/users/Wookloo","html_url":"https://github.com/Wookloo","followers_url":"https://api.github.com/users/Wookloo/followers","following_url":"https://api.github.com/users/Wookloo/following{/other_user}","gists_url":"https://api.github.com/users/Wookloo/gists{/gist_id}","starred_url":"https://api.github.com/users/Wookloo/starred{/owner}{/repo}","subscriptions_url":"https://api.github.com/users/Wookloo/subscriptions","organizations_url":"https://api.github.com/users/Wookloo/orgs","repos_url":"https://api.github.com/users/Wookloo/repos","events_url":"https://api.github.com/users/Wookloo/events{/privacy}","received_events_url":"https://api.github.com/users/Wookloo/received_events","type":"User","site_admin":false},"labels":[{"id":1694165746,"node_id":"MDU6TGFiZWwxNjk0MTY1NzQ2","url":"https://api.github.com/repos/pycaret/pycaret/labels/bug","name":"bug","color":"d73a4a","default":true,"description":"Something isn't working"}],"state":"closed","locked":false,"assignee":{"login":"pycaret","id":58118658,"node_id":"MDQ6VXNlcjU4MTE4NjU4","avatar_url":"https://avatars1.githubusercontent.com/u/58118658?v=4","gravatar_id":"","url":"https://api.github.com/users/pycaret","html_url":"https://github.com/pycaret","followers_url":"https://api.github.com/users/pycaret/followers","following_url":"https://api.github.com/users/pycaret/following{/other_user}","gists_url":"https://api.github.com/users/pycaret/gists{/gist_id}","starred_url":"https://api.github.com/users/pycaret/starred{/owner}{/repo}","subscriptions_url":"https://api.github.com/users/pycaret/subscriptions","organizations_url":"https://api.github.com/users/pycaret/orgs","repos_url":"https://api.github.com/users/pycaret/repos","events_url":"https://api.github.com/users/pycaret/events{/privacy}","received_events_url":"https://api.github.com/users/pycaret/received_events","type":"User","site_admin":false},"assignees":[{"login":"pycaret","id":58118658,"node_id":"MDQ6VXNlcjU4MTE4NjU4","avatar_url":"https://avatars1.githubusercontent.com/u/58118658?v=4","gravatar_id":"","url":"https://api.github.com/users/pycaret","html_url":"https://github.com/pycaret","followers_url":"https://api.github.com/users/pycaret/followers","following_url":"https://api.github.com/users/pycaret/following{/other_user}","gists_url":"https://api.github.com/users/pycaret/gists{/gist_id}","starred_url":"https://api.github.com/users/pycaret/starred{/owner}{/repo}","subscriptions_url":"https://api.github.com/users/pycaret/subscriptions","organizations_url":"https://api.github.com/users/pycaret/orgs","repos_url":"https://api.github.com/users/pycaret/repos","events_url":"https://api.github.com/users/pycaret/events{/privacy}","received_events_url":"https://api.github.com/users/pycaret/received_events","type":"User","site_admin":false}],"milestone":null,"comments":15,"created_at":"2020-08-24T08:13:40Z","updated_at":"2020-09-17T02:55:15Z","closed_at":"2020-08-31T16:52:52Z","author_association":"NONE","active_lock_reason":null,"body":"Hello,\r\n\r\nI have an issue when trying to re use my saved regression Model.\r\nI have been able to create use and save my model within the same session. \r\nHowever after i stop my session and want to load previously save model and make new prediction as per the Tutorial. \r\nI am loading the Model succesfully but after typing the cmd \"predict_model\" I'm getting an an \"Attribute error\"\r\n![image](https://user-images.githubusercontent.com/36540215/91018996-edbbb600-e622-11ea-85dd-00e2665549ce.png)\r\n\r\n![image](https://user-images.githubusercontent.com/36540215/91019106-10e66580-e623-11ea-956f-a8133b14efb4.png)\r\n\r\nI am getting this error on the computer i have develop the model in and the sample of data i m doing the prediction have the same frame/attributes only the size changed compare the previous prediction done successfully.\r\n\r\n\r\nHere is my pip and pd version \r\n![image](https://user-images.githubusercontent.com/36540215/91020133-a9c9b080-e624-11ea-8e7e-a5612b3c9149.png)\r\n\r\nThanks for your help!","performed_via_github_app":null},{"url":"https://api.github.com/repos/pycaret/pycaret/issues/423","repository_url":"https://api.github.com/repos/pycaret/pycaret","labels_url":"https://api.github.com/repos/pycaret/pycaret/issues/423/labels{/name}","comments_url":"https://api.github.com/repos/pycaret/pycaret/issues/423/comments","events_url":"https://api.github.com/repos/pycaret/pycaret/issues/423/events","html_url":"https://github.com/pycaret/pycaret/issues/423","id":677835150,"node_id":"MDU6SXNzdWU2Nzc4MzUxNTA=","number":423,"title":"Tune Model Never Completes","user":{"login":"brinew27","id":872698,"node_id":"MDQ6VXNlcjg3MjY5OA==","avatar_url":"https://avatars0.githubusercontent.com/u/872698?v=4","gravatar_id":"","url":"https://api.github.com/users/brinew27","html_url":"https://github.com/brinew27","followers_url":"https://api.github.com/users/brinew27/followers","following_url":"https://api.github.com/users/brinew27/following{/other_user}","gists_url":"https://api.github.com/users/brinew27/gists{/gist_id}","starred_url":"https://api.github.com/users/brinew27/starred{/owner}{/repo}","subscriptions_url":"https://api.github.com/users/brinew27/subscriptions","organizations_url":"https://api.github.com/users/brinew27/orgs","repos_url":"https://api.github.com/users/brinew27/repos","events_url":"https://api.github.com/users/brinew27/events{/privacy}","received_events_url":"https://api.github.com/users/brinew27/received_events","type":"User","site_admin":false},"labels":[{"id":1694165746,"node_id":"MDU6TGFiZWwxNjk0MTY1NzQ2","url":"https://api.github.com/repos/pycaret/pycaret/labels/bug","name":"bug","color":"d73a4a","default":true,"description":"Something isn't working"}],"state":"closed","locked":false,"assignee":null,"assignees":[],"milestone":null,"comments":4,"created_at":"2020-08-12T16:46:47Z","updated_at":"2020-08-18T17:21:29Z","closed_at":"2020-08-18T17:21:08Z","author_association":"NONE","active_lock_reason":null,"body":"Hi all,\r\n\r\nI'm enjoying PyCaret quite a bit so far. However, when I attempt to tune a model of any size (say 5 million rows), the tune model stop simply never progresses, it begins, gives the initial output and then never changes. I let it run for over 8 hours last night with no progress.\r\n\r\nThe model I'm attempting to tune is a GPU accelerated xgboost ('xgboost', tree_method = 'gpu_hist', gpu_id = 0). Training the model takes under 30 seconds even with 5 million rows. Chaging the model to not use GPU doesn't appear to make a difference.\r\n\r\nI have seen it finish once, but it was with many fewer rows, (say around 200K). I'm simply running \"tuned_xgb = tune_model(xgb, optimize='Precision')\".\r\n\r\nAny thoughts?\r\n\r\nThanks!","performed_via_github_app":null},{"url":"https://api.github.com/repos/pycaret/pycaret/issues/398","repository_url":"https://api.github.com/repos/pycaret/pycaret","labels_url":"https://api.github.com/repos/pycaret/pycaret/issues/398/labels{/name}","comments_url":"https://api.github.com/repos/pycaret/pycaret/issues/398/comments","events_url":"https://api.github.com/repos/pycaret/pycaret/issues/398/events","html_url":"https://github.com/pycaret/pycaret/issues/398","id":675626622,"node_id":"MDU6SXNzdWU2NzU2MjY2MjI=","number":398,"title":"Possible bug: test_size in train_test_split when sampling=True","user":{"login":"clgarciga","id":13739205,"node_id":"MDQ6VXNlcjEzNzM5MjA1","avatar_url":"https://avatars0.githubusercontent.com/u/13739205?v=4","gravatar_id":"","url":"https://api.github.com/users/clgarciga","html_url":"https://github.com/clgarciga","followers_url":"https://api.github.com/users/clgarciga/followers","following_url":"https://api.github.com/users/clgarciga/following{/other_user}","gists_url":"https://api.github.com/users/clgarciga/gists{/gist_id}","starred_url":"https://api.github.com/users/clgarciga/starred{/owner}{/repo}","subscriptions_url":"https://api.github.com/users/clgarciga/subscriptions","organizations_url":"https://api.github.com/users/clgarciga/orgs","repos_url":"https://api.github.com/users/clgarciga/repos","events_url":"https://api.github.com/users/clgarciga/events{/privacy}","received_events_url":"https://api.github.com/users/clgarciga/received_events","type":"User","site_admin":false},"labels":[{"id":1694165746,"node_id":"MDU6TGFiZWwxNjk0MTY1NzQ2","url":"https://api.github.com/repos/pycaret/pycaret/labels/bug","name":"bug","color":"d73a4a","default":true,"description":"Something isn't working"}],"state":"closed","locked":false,"assignee":null,"assignees":[],"milestone":null,"comments":3,"created_at":"2020-08-09T03:08:49Z","updated_at":"2020-08-16T16:44:31Z","closed_at":"2020-08-16T16:44:31Z","author_association":"CONTRIBUTOR","active_lock_reason":null,"body":"In function `setup` of `regression.py` and `classification.py`, when `sampling is True and data.shape[0] > 25000`, sampling and the train/test split proceeds as follows:\r\n\r\n```\r\nX_, X__, y_, y__ = train_test_split(X, y, test_size=1-i, stratify=y, random_state=seed, shuffle=data_split_shuffle)\r\nX_train, X_test, y_train, y_test = train_test_split(X_, y_, test_size=0.3, stratify=y_, random_state=seed, shuffle=data_split_shuffle)\r\n```\r\n\r\nMy question is whether or not `test_size` in the second line should be hardcoded to 0.3 or whether it should be `test_size = 1-train_size`, where `train_size` is the user-specified parameter in `setup`. \r\n\r\n","performed_via_github_app":null},{"url":"https://api.github.com/repos/pycaret/pycaret/issues/334","repository_url":"https://api.github.com/repos/pycaret/pycaret","labels_url":"https://api.github.com/repos/pycaret/pycaret/issues/334/labels{/name}","comments_url":"https://api.github.com/repos/pycaret/pycaret/issues/334/comments","events_url":"https://api.github.com/repos/pycaret/pycaret/issues/334/events","html_url":"https://github.com/pycaret/pycaret/issues/334","id":672155137,"node_id":"MDU6SXNzdWU2NzIxNTUxMzc=","number":334,"title":"custom parameters are not working for clustering algorithms.","user":{"login":"sathishkumar369","id":40235632,"node_id":"MDQ6VXNlcjQwMjM1NjMy","avatar_url":"https://avatars3.githubusercontent.com/u/40235632?v=4","gravatar_id":"","url":"https://api.github.com/users/sathishkumar369","html_url":"https://github.com/sathishkumar369","followers_url":"https://api.github.com/users/sathishkumar369/followers","following_url":"https://api.github.com/users/sathishkumar369/following{/other_user}","gists_url":"https://api.github.com/users/sathishkumar369/gists{/gist_id}","starred_url":"https://api.github.com/users/sathishkumar369/starred{/owner}{/repo}","subscriptions_url":"https://api.github.com/users/sathishkumar369/subscriptions","organizations_url":"https://api.github.com/users/sathishkumar369/orgs","repos_url":"https://api.github.com/users/sathishkumar369/repos","events_url":"https://api.github.com/users/sathishkumar369/events{/privacy}","received_events_url":"https://api.github.com/users/sathishkumar369/received_events","type":"User","site_admin":false},"labels":[{"id":1694165746,"node_id":"MDU6TGFiZWwxNjk0MTY1NzQ2","url":"https://api.github.com/repos/pycaret/pycaret/labels/bug","name":"bug","color":"d73a4a","default":true,"description":"Something isn't working"}],"state":"closed","locked":false,"assignee":null,"assignees":[],"milestone":null,"comments":4,"created_at":"2020-08-03T15:23:57Z","updated_at":"2020-08-14T19:48:19Z","closed_at":"2020-08-14T19:48:19Z","author_association":"NONE","active_lock_reason":null,"body":"Hi pycaret team!\r\nLoved your work for pycaret 2.0 version.\r\n\r\ncustom parameters are not working for clustering algorithms, I have customized parameters for kmeans as well as dbscan. it's throwing an error.\r\nI checked for the classification one with random forest by changing criterion= \"gini to entropy\", it's worked well.\r\n\r\nPFA.\r\n![Screenshot (324)](https://user-images.githubusercontent.com/40235632/89198844-68b52200-d5cb-11ea-86ee-0a7d033ada5c.png)\r\n","performed_via_github_app":null},{"url":"https://api.github.com/repos/pycaret/pycaret/issues/317","repository_url":"https://api.github.com/repos/pycaret/pycaret","labels_url":"https://api.github.com/repos/pycaret/pycaret/issues/317/labels{/name}","comments_url":"https://api.github.com/repos/pycaret/pycaret/issues/317/comments","events_url":"https://api.github.com/repos/pycaret/pycaret/issues/317/events","html_url":"https://github.com/pycaret/pycaret/issues/317","id":671589215,"node_id":"MDU6SXNzdWU2NzE1ODkyMTU=","number":317,"title":"AttributeError in plot_model for 2D Cluster PCA Plot","user":{"login":"mtdearing","id":8498292,"node_id":"MDQ6VXNlcjg0OTgyOTI=","avatar_url":"https://avatars3.githubusercontent.com/u/8498292?v=4","gravatar_id":"","url":"https://api.github.com/users/mtdearing","html_url":"https://github.com/mtdearing","followers_url":"https://api.github.com/users/mtdearing/followers","following_url":"https://api.github.com/users/mtdearing/following{/other_user}","gists_url":"https://api.github.com/users/mtdearing/gists{/gist_id}","starred_url":"https://api.github.com/users/mtdearing/starred{/owner}{/repo}","subscriptions_url":"https://api.github.com/users/mtdearing/subscriptions","organizations_url":"https://api.github.com/users/mtdearing/orgs","repos_url":"https://api.github.com/users/mtdearing/repos","events_url":"https://api.github.com/users/mtdearing/events{/privacy}","received_events_url":"https://api.github.com/users/mtdearing/received_events","type":"User","site_admin":false},"labels":[{"id":1694165746,"node_id":"MDU6TGFiZWwxNjk0MTY1NzQ2","url":"https://api.github.com/repos/pycaret/pycaret/labels/bug","name":"bug","color":"d73a4a","default":true,"description":"Something isn't working"}],"state":"closed","locked":false,"assignee":null,"assignees":[],"milestone":null,"comments":5,"created_at":"2020-08-02T10:10:41Z","updated_at":"2020-08-06T19:20:43Z","closed_at":"2020-08-06T19:20:43Z","author_association":"NONE","active_lock_reason":null,"body":"For a clustering model I've been working on with pycaret pre-2.0, I was generating the PCA plot successfully. I updated to 2.0, and receive the error below when running plot_model(<my_model>, plot='cluster').  The other plot types, e.g., 'elbow', generate a plot output without an error. Does the error below suggest I would have a feature format issue in my dataset?\r\n\r\n```\r\n~/miniconda3/lib/python3.7/site-packages/pycaret/clustering.py in plot_model(model, plot, feature, label, save, system)\r\n   3416 \r\n   3417         for i in pca_.Cluster:\r\n-> 3418             a = int(i.split()[1])\r\n   3419             clus_num.append(a)\r\n   3420 \r\n\r\nAttributeError: 'float' object has no attribute 'split'\r\n```","performed_via_github_app":null},{"url":"https://api.github.com/repos/pycaret/pycaret/issues/265","repository_url":"https://api.github.com/repos/pycaret/pycaret","labels_url":"https://api.github.com/repos/pycaret/pycaret/issues/265/labels{/name}","comments_url":"https://api.github.com/repos/pycaret/pycaret/issues/265/comments","events_url":"https://api.github.com/repos/pycaret/pycaret/issues/265/events","html_url":"https://github.com/pycaret/pycaret/issues/265","id":652350877,"node_id":"MDU6SXNzdWU2NTIzNTA4Nzc=","number":265,"title":"UnboundLocalError: local variable 'visualizer' referenced before assignment","user":{"login":"sumeshmr","id":24572078,"node_id":"MDQ6VXNlcjI0NTcyMDc4","avatar_url":"https://avatars0.githubusercontent.com/u/24572078?v=4","gravatar_id":"","url":"https://api.github.com/users/sumeshmr","html_url":"https://github.com/sumeshmr","followers_url":"https://api.github.com/users/sumeshmr/followers","following_url":"https://api.github.com/users/sumeshmr/following{/other_user}","gists_url":"https://api.github.com/users/sumeshmr/gists{/gist_id}","starred_url":"https://api.github.com/users/sumeshmr/starred{/owner}{/repo}","subscriptions_url":"https://api.github.com/users/sumeshmr/subscriptions","organizations_url":"https://api.github.com/users/sumeshmr/orgs","repos_url":"https://api.github.com/users/sumeshmr/repos","events_url":"https://api.github.com/users/sumeshmr/events{/privacy}","received_events_url":"https://api.github.com/users/sumeshmr/received_events","type":"User","site_admin":false},"labels":[{"id":1694165746,"node_id":"MDU6TGFiZWwxNjk0MTY1NzQ2","url":"https://api.github.com/repos/pycaret/pycaret/labels/bug","name":"bug","color":"d73a4a","default":true,"description":"Something isn't working"}],"state":"closed","locked":false,"assignee":null,"assignees":[],"milestone":null,"comments":3,"created_at":"2020-07-07T14:03:01Z","updated_at":"2020-07-30T19:34:57Z","closed_at":"2020-07-30T19:34:57Z","author_association":"NONE","active_lock_reason":null,"body":"Hello,\r\n\r\nI was trying the nightly build version(pycaret-nightly).\r\nI got the below error when I tried the **Validation Curve** in **evaluate_model**\r\n\r\n![image](https://user-images.githubusercontent.com/24572078/86792957-a7f75e00-c073-11ea-85ae-5038c8bbbcce.png)\r\n","performed_via_github_app":null},{"url":"https://api.github.com/repos/pycaret/pycaret/issues/259","repository_url":"https://api.github.com/repos/pycaret/pycaret","labels_url":"https://api.github.com/repos/pycaret/pycaret/issues/259/labels{/name}","comments_url":"https://api.github.com/repos/pycaret/pycaret/issues/259/comments","events_url":"https://api.github.com/repos/pycaret/pycaret/issues/259/events","html_url":"https://github.com/pycaret/pycaret/issues/259","id":648726153,"node_id":"MDU6SXNzdWU2NDg3MjYxNTM=","number":259,"title":"Getting an error while running the topic modeling","user":{"login":"sathishkumar369","id":40235632,"node_id":"MDQ6VXNlcjQwMjM1NjMy","avatar_url":"https://avatars3.githubusercontent.com/u/40235632?v=4","gravatar_id":"","url":"https://api.github.com/users/sathishkumar369","html_url":"https://github.com/sathishkumar369","followers_url":"https://api.github.com/users/sathishkumar369/followers","following_url":"https://api.github.com/users/sathishkumar369/following{/other_user}","gists_url":"https://api.github.com/users/sathishkumar369/gists{/gist_id}","starred_url":"https://api.github.com/users/sathishkumar369/starred{/owner}{/repo}","subscriptions_url":"https://api.github.com/users/sathishkumar369/subscriptions","organizations_url":"https://api.github.com/users/sathishkumar369/orgs","repos_url":"https://api.github.com/users/sathishkumar369/repos","events_url":"https://api.github.com/users/sathishkumar369/events{/privacy}","received_events_url":"https://api.github.com/users/sathishkumar369/received_events","type":"User","site_admin":false},"labels":[{"id":1694165746,"node_id":"MDU6TGFiZWwxNjk0MTY1NzQ2","url":"https://api.github.com/repos/pycaret/pycaret/labels/bug","name":"bug","color":"d73a4a","default":true,"description":"Something isn't working"}],"state":"closed","locked":false,"assignee":null,"assignees":[],"milestone":null,"comments":3,"created_at":"2020-07-01T06:57:47Z","updated_at":"2020-07-08T07:01:13Z","closed_at":"2020-07-08T07:01:13Z","author_association":"NONE","active_lock_reason":null,"body":"Hi pycaret team,\r\nwhen I was using setup for topic modeling it's giving me an error\r\n\r\nPFA\r\n\r\n![Screenshot (233)](https://user-images.githubusercontent.com/40235632/86212473-c2be6400-bb95-11ea-917d-41352e33b4c3.png)\r\n![Screenshot (234)](https://user-images.githubusercontent.com/40235632/86212485-c94cdb80-bb95-11ea-9c70-46518dde8748.png)\r\n\r\nwhen I have run this from scratch also I got the same error.\r\nbut I was able to fix it in scratch,just by increasing the max_length of the text.\r\nbut I don't know how to fix it in pycaret.\r\n\r\nI used this code to fix it on scratch.\r\n\r\nnlp = spacy.load(\"en_core_web_sm\", disable=['parser', 'ner'])\r\nnlp.max_length = 3000000","performed_via_github_app":null},{"url":"https://api.github.com/repos/pycaret/pycaret/issues/248","repository_url":"https://api.github.com/repos/pycaret/pycaret","labels_url":"https://api.github.com/repos/pycaret/pycaret/issues/248/labels{/name}","comments_url":"https://api.github.com/repos/pycaret/pycaret/issues/248/comments","events_url":"https://api.github.com/repos/pycaret/pycaret/issues/248/events","html_url":"https://github.com/pycaret/pycaret/issues/248","id":646286156,"node_id":"MDU6SXNzdWU2NDYyODYxNTY=","number":248,"title":"AttributeError: 'NoneType' object has no attribute 'flush' outside notebook","user":{"login":"skrunt7","id":16330357,"node_id":"MDQ6VXNlcjE2MzMwMzU3","avatar_url":"https://avatars0.githubusercontent.com/u/16330357?v=4","gravatar_id":"","url":"https://api.github.com/users/skrunt7","html_url":"https://github.com/skrunt7","followers_url":"https://api.github.com/users/skrunt7/followers","following_url":"https://api.github.com/users/skrunt7/following{/other_user}","gists_url":"https://api.github.com/users/skrunt7/gists{/gist_id}","starred_url":"https://api.github.com/users/skrunt7/starred{/owner}{/repo}","subscriptions_url":"https://api.github.com/users/skrunt7/subscriptions","organizations_url":"https://api.github.com/users/skrunt7/orgs","repos_url":"https://api.github.com/users/skrunt7/repos","events_url":"https://api.github.com/users/skrunt7/events{/privacy}","received_events_url":"https://api.github.com/users/skrunt7/received_events","type":"User","site_admin":false},"labels":[{"id":1694165746,"node_id":"MDU6TGFiZWwxNjk0MTY1NzQ2","url":"https://api.github.com/repos/pycaret/pycaret/labels/bug","name":"bug","color":"d73a4a","default":true,"description":"Something isn't working"}],"state":"closed","locked":false,"assignee":null,"assignees":[],"milestone":null,"comments":4,"created_at":"2020-06-26T14:03:50Z","updated_at":"2020-07-30T22:33:24Z","closed_at":"2020-07-30T22:33:24Z","author_association":"NONE","active_lock_reason":null,"body":"Does pycaret support usage outside of notebooks utilizing IPython?\r\n\r\nI am trying to deploy models in production (outside of Jupiter notebooks) by loading models that I saved from a notebook but I get errors related to IPython. The model loads properly but fails on predict_model due to clear_output() on line 6636.","performed_via_github_app":null},{"url":"https://api.github.com/repos/pycaret/pycaret/issues/235","repository_url":"https://api.github.com/repos/pycaret/pycaret","labels_url":"https://api.github.com/repos/pycaret/pycaret/issues/235/labels{/name}","comments_url":"https://api.github.com/repos/pycaret/pycaret/issues/235/comments","events_url":"https://api.github.com/repos/pycaret/pycaret/issues/235/events","html_url":"https://github.com/pycaret/pycaret/issues/235","id":641705446,"node_id":"MDU6SXNzdWU2NDE3MDU0NDY=","number":235,"title":"Clustering plot_model changing the index of the dataset","user":{"login":"ZamoraAndres","id":1726174,"node_id":"MDQ6VXNlcjE3MjYxNzQ=","avatar_url":"https://avatars3.githubusercontent.com/u/1726174?v=4","gravatar_id":"","url":"https://api.github.com/users/ZamoraAndres","html_url":"https://github.com/ZamoraAndres","followers_url":"https://api.github.com/users/ZamoraAndres/followers","following_url":"https://api.github.com/users/ZamoraAndres/following{/other_user}","gists_url":"https://api.github.com/users/ZamoraAndres/gists{/gist_id}","starred_url":"https://api.github.com/users/ZamoraAndres/starred{/owner}{/repo}","subscriptions_url":"https://api.github.com/users/ZamoraAndres/subscriptions","organizations_url":"https://api.github.com/users/ZamoraAndres/orgs","repos_url":"https://api.github.com/users/ZamoraAndres/repos","events_url":"https://api.github.com/users/ZamoraAndres/events{/privacy}","received_events_url":"https://api.github.com/users/ZamoraAndres/received_events","type":"User","site_admin":false},"labels":[{"id":1694165746,"node_id":"MDU6TGFiZWwxNjk0MTY1NzQ2","url":"https://api.github.com/repos/pycaret/pycaret/labels/bug","name":"bug","color":"d73a4a","default":true,"description":"Something isn't working"}],"state":"closed","locked":false,"assignee":null,"assignees":[],"milestone":null,"comments":3,"created_at":"2020-06-19T05:00:30Z","updated_at":"2020-07-30T21:45:12Z","closed_at":"2020-07-30T21:45:12Z","author_association":"NONE","active_lock_reason":null,"body":"I found an issue when executing the function:\r\ndef plot_model(model, plot='cluster', feature = None, label = False)\r\n\r\nThis line is changing the index of the dataset and wrongly assigns the cluster label:\r\n[line 2528] b.reset_index(inplace=True, drop=True)\r\n\r\nIf you remove the line, the plot shows correctly the cluster label for each row.\r\n\r\n","performed_via_github_app":null},{"url":"https://api.github.com/repos/pycaret/pycaret/issues/225","repository_url":"https://api.github.com/repos/pycaret/pycaret","labels_url":"https://api.github.com/repos/pycaret/pycaret/issues/225/labels{/name}","comments_url":"https://api.github.com/repos/pycaret/pycaret/issues/225/comments","events_url":"https://api.github.com/repos/pycaret/pycaret/issues/225/events","html_url":"https://github.com/pycaret/pycaret/issues/225","id":640104145,"node_id":"MDU6SXNzdWU2NDAxMDQxNDU=","number":225,"title":"display undefined in datasets.py","user":{"login":"hermandr","id":10177608,"node_id":"MDQ6VXNlcjEwMTc3NjA4","avatar_url":"https://avatars2.githubusercontent.com/u/10177608?v=4","gravatar_id":"","url":"https://api.github.com/users/hermandr","html_url":"https://github.com/hermandr","followers_url":"https://api.github.com/users/hermandr/followers","following_url":"https://api.github.com/users/hermandr/following{/other_user}","gists_url":"https://api.github.com/users/hermandr/gists{/gist_id}","starred_url":"https://api.github.com/users/hermandr/starred{/owner}{/repo}","subscriptions_url":"https://api.github.com/users/hermandr/subscriptions","organizations_url":"https://api.github.com/users/hermandr/orgs","repos_url":"https://api.github.com/users/hermandr/repos","events_url":"https://api.github.com/users/hermandr/events{/privacy}","received_events_url":"https://api.github.com/users/hermandr/received_events","type":"User","site_admin":false},"labels":[{"id":1694165746,"node_id":"MDU6TGFiZWwxNjk0MTY1NzQ2","url":"https://api.github.com/repos/pycaret/pycaret/labels/bug","name":"bug","color":"d73a4a","default":true,"description":"Something isn't working"}],"state":"closed","locked":false,"assignee":null,"assignees":[],"milestone":null,"comments":1,"created_at":"2020-06-17T03:06:33Z","updated_at":"2020-07-30T19:33:21Z","closed_at":"2020-07-30T19:33:21Z","author_association":"NONE","active_lock_reason":null,"body":"Hi,\r\n\r\nI am using pycaret in rstudio.\r\n\r\n```\r\nfrom IPython.display import display\r\nimport numpy as np\r\nimport pandas as pd\r\nimport pycaret\r\nfrom pycaret.datasets import get_data\r\n\r\ndataset = get_data('credit')\r\n```\r\n\r\nReturns this error:\r\n```\r\nNameError: name 'display' is not defined\r\n\r\nDetailed traceback: \r\n  File \"<string>\", line 1, in <module>\r\n  File \"C:\\Users\\herma\\AppData\\Local\\conda\\conda\\envs\\r-reticulate\\lib\\site-packages\\pycaret\\datasets.py\", line 77, in get_data\r\n    display(data.head())\r\n```\r\nNeed to include `import IPython`\r\n\r\nHerman","performed_via_github_app":null},{"url":"https://api.github.com/repos/pycaret/pycaret/issues/193","repository_url":"https://api.github.com/repos/pycaret/pycaret","labels_url":"https://api.github.com/repos/pycaret/pycaret/issues/193/labels{/name}","comments_url":"https://api.github.com/repos/pycaret/pycaret/issues/193/comments","events_url":"https://api.github.com/repos/pycaret/pycaret/issues/193/events","html_url":"https://github.com/pycaret/pycaret/issues/193","id":630169424,"node_id":"MDU6SXNzdWU2MzAxNjk0MjQ=","number":193,"title":"setup() in clustering doesn't support passing silent=True","user":{"login":"agrawalparth08","id":5490997,"node_id":"MDQ6VXNlcjU0OTA5OTc=","avatar_url":"https://avatars3.githubusercontent.com/u/5490997?v=4","gravatar_id":"","url":"https://api.github.com/users/agrawalparth08","html_url":"https://github.com/agrawalparth08","followers_url":"https://api.github.com/users/agrawalparth08/followers","following_url":"https://api.github.com/users/agrawalparth08/following{/other_user}","gists_url":"https://api.github.com/users/agrawalparth08/gists{/gist_id}","starred_url":"https://api.github.com/users/agrawalparth08/starred{/owner}{/repo}","subscriptions_url":"https://api.github.com/users/agrawalparth08/subscriptions","organizations_url":"https://api.github.com/users/agrawalparth08/orgs","repos_url":"https://api.github.com/users/agrawalparth08/repos","events_url":"https://api.github.com/users/agrawalparth08/events{/privacy}","received_events_url":"https://api.github.com/users/agrawalparth08/received_events","type":"User","site_admin":false},"labels":[{"id":1694165746,"node_id":"MDU6TGFiZWwxNjk0MTY1NzQ2","url":"https://api.github.com/repos/pycaret/pycaret/labels/bug","name":"bug","color":"d73a4a","default":true,"description":"Something isn't working"}],"state":"closed","locked":false,"assignee":null,"assignees":[],"milestone":null,"comments":2,"created_at":"2020-06-03T17:06:31Z","updated_at":"2020-07-30T22:32:39Z","closed_at":"2020-07-30T22:32:39Z","author_association":"NONE","active_lock_reason":null,"body":"from pycaret.clustering import *\r\ndata_setup = setup(df, normalize = True, silent=True, session_id = 42,verbose=False)\r\n\r\n`_TypeError: setup() got an unexpected keyword argument 'silent'_`","performed_via_github_app":null},{"url":"https://api.github.com/repos/pycaret/pycaret/issues/175","repository_url":"https://api.github.com/repos/pycaret/pycaret","labels_url":"https://api.github.com/repos/pycaret/pycaret/issues/175/labels{/name}","comments_url":"https://api.github.com/repos/pycaret/pycaret/issues/175/comments","events_url":"https://api.github.com/repos/pycaret/pycaret/issues/175/events","html_url":"https://github.com/pycaret/pycaret/issues/175","id":624230909,"node_id":"MDU6SXNzdWU2MjQyMzA5MDk=","number":175,"title":"NameError: name 'display_id' is not defined when executing code in IDE","user":{"login":"HenriqueAJNB","id":54143210,"node_id":"MDQ6VXNlcjU0MTQzMjEw","avatar_url":"https://avatars3.githubusercontent.com/u/54143210?v=4","gravatar_id":"","url":"https://api.github.com/users/HenriqueAJNB","html_url":"https://github.com/HenriqueAJNB","followers_url":"https://api.github.com/users/HenriqueAJNB/followers","following_url":"https://api.github.com/users/HenriqueAJNB/following{/other_user}","gists_url":"https://api.github.com/users/HenriqueAJNB/gists{/gist_id}","starred_url":"https://api.github.com/users/HenriqueAJNB/starred{/owner}{/repo}","subscriptions_url":"https://api.github.com/users/HenriqueAJNB/subscriptions","organizations_url":"https://api.github.com/users/HenriqueAJNB/orgs","repos_url":"https://api.github.com/users/HenriqueAJNB/repos","events_url":"https://api.github.com/users/HenriqueAJNB/events{/privacy}","received_events_url":"https://api.github.com/users/HenriqueAJNB/received_events","type":"User","site_admin":false},"labels":[{"id":1694165746,"node_id":"MDU6TGFiZWwxNjk0MTY1NzQ2","url":"https://api.github.com/repos/pycaret/pycaret/labels/bug","name":"bug","color":"d73a4a","default":true,"description":"Something isn't working"},{"id":1694165751,"node_id":"MDU6TGFiZWwxNjk0MTY1NzUx","url":"https://api.github.com/repos/pycaret/pycaret/labels/duplicate","name":"duplicate","color":"cfd3d7","default":true,"description":"This issue or pull request already exists"}],"state":"closed","locked":false,"assignee":null,"assignees":[],"milestone":null,"comments":1,"created_at":"2020-05-25T11:11:36Z","updated_at":"2020-06-05T21:11:49Z","closed_at":"2020-06-05T21:11:49Z","author_association":"NONE","active_lock_reason":null,"body":"Hi there, \r\n\r\nI just got this error while coding execution in Visual Studio Code.\r\n\r\n`NameError: name 'display_id' is not defined`\r\n\r\nAnd here is code tried:\r\n\r\n```\r\nfrom sklearn.datasets import load_boston\r\nimport pandas as pd\r\nfrom pycaret import regression\r\n\r\nboston = load_boston()\r\n\r\ndf = pd.DataFrame(data=boston[\"data\"], columns=boston[\"feature_names\"])\r\ndf[\"MEDV\"] = boston[\"target\"]\r\n\r\nexp_reg = regression.setup(\r\n    data=df,\r\n    target=\"MEDV\",\r\n    train_size=0.7,\r\n    normalize=True,\r\n    remove_outliers=True\r\n)\r\n\r\nmodel = regression.create_model(estimator='lr')\r\n```\r\n\r\nIs there somehow to check if user is executing code either in prompt, IDE or Jupyter Notebook/Google Colab? \r\n\r\nHow can I contribute to solve this problem?\r\n\r\nFor this specific case, I just comment 5 lines and it worked. \r\n\r\n```\r\n1689 # if verbose:\r\n1690 #     display_ = display(master_display, display_id=True)\r\n1691 #     display_id = display_.display_id\r\n...\r\n2015 # if verbose:\r\n2016 #     update_display(master_display, display_id = display_id)\r\n```\r\n\r\nThanks!\r\n\r\n\r\n","performed_via_github_app":null},{"url":"https://api.github.com/repos/pycaret/pycaret/issues/140","repository_url":"https://api.github.com/repos/pycaret/pycaret","labels_url":"https://api.github.com/repos/pycaret/pycaret/issues/140/labels{/name}","comments_url":"https://api.github.com/repos/pycaret/pycaret/issues/140/comments","events_url":"https://api.github.com/repos/pycaret/pycaret/issues/140/events","html_url":"https://github.com/pycaret/pycaret/issues/140","id":619165842,"node_id":"MDU6SXNzdWU2MTkxNjU4NDI=","number":140,"title":"NLP num of line doesn't match error from colab","user":{"login":"DaiZack","id":45176371,"node_id":"MDQ6VXNlcjQ1MTc2Mzcx","avatar_url":"https://avatars0.githubusercontent.com/u/45176371?v=4","gravatar_id":"","url":"https://api.github.com/users/DaiZack","html_url":"https://github.com/DaiZack","followers_url":"https://api.github.com/users/DaiZack/followers","following_url":"https://api.github.com/users/DaiZack/following{/other_user}","gists_url":"https://api.github.com/users/DaiZack/gists{/gist_id}","starred_url":"https://api.github.com/users/DaiZack/starred{/owner}{/repo}","subscriptions_url":"https://api.github.com/users/DaiZack/subscriptions","organizations_url":"https://api.github.com/users/DaiZack/orgs","repos_url":"https://api.github.com/users/DaiZack/repos","events_url":"https://api.github.com/users/DaiZack/events{/privacy}","received_events_url":"https://api.github.com/users/DaiZack/received_events","type":"User","site_admin":false},"labels":[{"id":1694165746,"node_id":"MDU6TGFiZWwxNjk0MTY1NzQ2","url":"https://api.github.com/repos/pycaret/pycaret/labels/bug","name":"bug","color":"d73a4a","default":true,"description":"Something isn't working"}],"state":"closed","locked":false,"assignee":null,"assignees":[],"milestone":null,"comments":2,"created_at":"2020-05-15T18:39:23Z","updated_at":"2020-09-10T17:15:31Z","closed_at":"2020-09-10T17:15:31Z","author_association":"NONE","active_lock_reason":null,"body":"nlp.py\r\n\r\nline 141\r\n\r\n `   try:\r\n        max_sub = len(data[target].values.tolist())\r\n    except:\r\n        max_sub = len(data)`\r\n\r\nWhen the data frame target column has empty values, it courses num of lines not match error in model_plot step.\r\n\r\nPS: I ran it from Colab\r\n\r\n","performed_via_github_app":null},{"url":"https://api.github.com/repos/pycaret/pycaret/issues/136","repository_url":"https://api.github.com/repos/pycaret/pycaret","labels_url":"https://api.github.com/repos/pycaret/pycaret/issues/136/labels{/name}","comments_url":"https://api.github.com/repos/pycaret/pycaret/issues/136/comments","events_url":"https://api.github.com/repos/pycaret/pycaret/issues/136/events","html_url":"https://github.com/pycaret/pycaret/issues/136","id":618684402,"node_id":"MDU6SXNzdWU2MTg2ODQ0MDI=","number":136,"title":"AttributeError: 'NoneType' object has no attribute 'display_id'","user":{"login":"gillbates","id":783547,"node_id":"MDQ6VXNlcjc4MzU0Nw==","avatar_url":"https://avatars0.githubusercontent.com/u/783547?v=4","gravatar_id":"","url":"https://api.github.com/users/gillbates","html_url":"https://github.com/gillbates","followers_url":"https://api.github.com/users/gillbates/followers","following_url":"https://api.github.com/users/gillbates/following{/other_user}","gists_url":"https://api.github.com/users/gillbates/gists{/gist_id}","starred_url":"https://api.github.com/users/gillbates/starred{/owner}{/repo}","subscriptions_url":"https://api.github.com/users/gillbates/subscriptions","organizations_url":"https://api.github.com/users/gillbates/orgs","repos_url":"https://api.github.com/users/gillbates/repos","events_url":"https://api.github.com/users/gillbates/events{/privacy}","received_events_url":"https://api.github.com/users/gillbates/received_events","type":"User","site_admin":false},"labels":[{"id":1694165746,"node_id":"MDU6TGFiZWwxNjk0MTY1NzQ2","url":"https://api.github.com/repos/pycaret/pycaret/labels/bug","name":"bug","color":"d73a4a","default":true,"description":"Something isn't working"}],"state":"closed","locked":false,"assignee":null,"assignees":[],"milestone":null,"comments":3,"created_at":"2020-05-15T04:13:12Z","updated_at":"2020-07-30T19:37:36Z","closed_at":"2020-07-30T19:37:36Z","author_association":"NONE","active_lock_reason":null,"body":"Hi pycaret team,\r\n\r\nwhen i try following code according to the tutorial\r\n\r\n\r\n\r\n`\r\ndiabetes = pd.read_csv('/Users/xxx/projects/github/pycaret/datasets/diabetes.csv')\r\nclf1 = setup(data=diabetes, target='Class variable')\r\n\r\ncompare_models()\r\n\r\n`\r\n\r\nwhen I cloned the repo and use following code from tutorial.\r\n`\r\nTraceback (most recent call last):\r\n  File \"/Users/xxx/projects/python/pycaret/test.py\", line 15, in <module>\r\n    compare_models()\r\n  File \"/Users/xxx/projects/python/pycaret/venv/lib/python3.7/site-packages/pycaret/classification.py\", line 3185, in compare_models\r\n    display_id = display_.display_id\r\nAttributeError: 'NoneType' object has no attribute 'display_id'\r\n`\r\n\r\n\r\nrunning on python 3.7.7 macos\r\n\r\nAnyone could help?","performed_via_github_app":null},{"url":"https://api.github.com/repos/pycaret/pycaret/issues/135","repository_url":"https://api.github.com/repos/pycaret/pycaret","labels_url":"https://api.github.com/repos/pycaret/pycaret/issues/135/labels{/name}","comments_url":"https://api.github.com/repos/pycaret/pycaret/issues/135/comments","events_url":"https://api.github.com/repos/pycaret/pycaret/issues/135/events","html_url":"https://github.com/pycaret/pycaret/issues/135","id":618376206,"node_id":"MDU6SXNzdWU2MTgzNzYyMDY=","number":135,"title":"Could not convert STR column to FLOAT when this column has missing values","user":{"login":"FaridAhamadaGunners","id":11425198,"node_id":"MDQ6VXNlcjExNDI1MTk4","avatar_url":"https://avatars2.githubusercontent.com/u/11425198?v=4","gravatar_id":"","url":"https://api.github.com/users/FaridAhamadaGunners","html_url":"https://github.com/FaridAhamadaGunners","followers_url":"https://api.github.com/users/FaridAhamadaGunners/followers","following_url":"https://api.github.com/users/FaridAhamadaGunners/following{/other_user}","gists_url":"https://api.github.com/users/FaridAhamadaGunners/gists{/gist_id}","starred_url":"https://api.github.com/users/FaridAhamadaGunners/starred{/owner}{/repo}","subscriptions_url":"https://api.github.com/users/FaridAhamadaGunners/subscriptions","organizations_url":"https://api.github.com/users/FaridAhamadaGunners/orgs","repos_url":"https://api.github.com/users/FaridAhamadaGunners/repos","events_url":"https://api.github.com/users/FaridAhamadaGunners/events{/privacy}","received_events_url":"https://api.github.com/users/FaridAhamadaGunners/received_events","type":"User","site_admin":false},"labels":[{"id":1694165746,"node_id":"MDU6TGFiZWwxNjk0MTY1NzQ2","url":"https://api.github.com/repos/pycaret/pycaret/labels/bug","name":"bug","color":"d73a4a","default":true,"description":"Something isn't working"}],"state":"closed","locked":false,"assignee":null,"assignees":[],"milestone":null,"comments":2,"created_at":"2020-05-14T16:40:34Z","updated_at":"2020-07-30T19:37:48Z","closed_at":"2020-07-30T19:37:25Z","author_association":"NONE","active_lock_reason":null,"body":"I load a dataset (8000,22) with a string column contains float numbers. So the setup() function infer that this column is categorical because this column contains whitespace characters. \r\nSo when i force the setup() function with the parameter numeric_features set to with this column \r\n\r\nI encountered this error : ValueError: could not convert string to float \r\n\r\nWhen i debug the code i see that in the script preprocess.py you use the function .astype(float64) for conversion. I think you should use the pandas function to_numeric() with the parameter errors set to 'coerce' and the parameter downcast to 'integer'  or 'float or whatever. This function with theses settings will convert any columns in numeric and will force the unrecognized values to NaN.","performed_via_github_app":null},{"url":"https://api.github.com/repos/pycaret/pycaret/issues/120","repository_url":"https://api.github.com/repos/pycaret/pycaret","labels_url":"https://api.github.com/repos/pycaret/pycaret/issues/120/labels{/name}","comments_url":"https://api.github.com/repos/pycaret/pycaret/issues/120/comments","events_url":"https://api.github.com/repos/pycaret/pycaret/issues/120/events","html_url":"https://github.com/pycaret/pycaret/issues/120","id":615435902,"node_id":"MDU6SXNzdWU2MTU0MzU5MDI=","number":120,"title":"TypeError: 'int' object is not iterable","user":{"login":"TonyTnT","id":43055856,"node_id":"MDQ6VXNlcjQzMDU1ODU2","avatar_url":"https://avatars1.githubusercontent.com/u/43055856?v=4","gravatar_id":"","url":"https://api.github.com/users/TonyTnT","html_url":"https://github.com/TonyTnT","followers_url":"https://api.github.com/users/TonyTnT/followers","following_url":"https://api.github.com/users/TonyTnT/following{/other_user}","gists_url":"https://api.github.com/users/TonyTnT/gists{/gist_id}","starred_url":"https://api.github.com/users/TonyTnT/starred{/owner}{/repo}","subscriptions_url":"https://api.github.com/users/TonyTnT/subscriptions","organizations_url":"https://api.github.com/users/TonyTnT/orgs","repos_url":"https://api.github.com/users/TonyTnT/repos","events_url":"https://api.github.com/users/TonyTnT/events{/privacy}","received_events_url":"https://api.github.com/users/TonyTnT/received_events","type":"User","site_admin":false},"labels":[{"id":1694165746,"node_id":"MDU6TGFiZWwxNjk0MTY1NzQ2","url":"https://api.github.com/repos/pycaret/pycaret/labels/bug","name":"bug","color":"d73a4a","default":true,"description":"Something isn't working"},{"id":1694165751,"node_id":"MDU6TGFiZWwxNjk0MTY1NzUx","url":"https://api.github.com/repos/pycaret/pycaret/labels/duplicate","name":"duplicate","color":"cfd3d7","default":true,"description":"This issue or pull request already exists"}],"state":"closed","locked":false,"assignee":null,"assignees":[],"milestone":null,"comments":2,"created_at":"2020-05-10T17:16:48Z","updated_at":"2020-05-11T01:33:26Z","closed_at":"2020-05-11T01:33:26Z","author_association":"NONE","active_lock_reason":null,"body":"when i loading my data it shows that\r\n![image](https://user-images.githubusercontent.com/43055856/81505830-d6331880-9324-11ea-8a21-1b23aa65e379.png)\r\n\r\ni think there is no problem in my data\r\n![image](https://user-images.githubusercontent.com/43055856/81505848-f531aa80-9324-11ea-9511-ec64cb7831fa.png)\r\n\r\n\r\nthis is my data\r\n![image](https://user-images.githubusercontent.com/43055856/81505818-bef42b00-9324-11ea-8f5d-3858d0c6e79a.png)\r\n\r\nso could you tell me what went wrong?","performed_via_github_app":null},{"url":"https://api.github.com/repos/pycaret/pycaret/issues/117","repository_url":"https://api.github.com/repos/pycaret/pycaret","labels_url":"https://api.github.com/repos/pycaret/pycaret/issues/117/labels{/name}","comments_url":"https://api.github.com/repos/pycaret/pycaret/issues/117/comments","events_url":"https://api.github.com/repos/pycaret/pycaret/issues/117/events","html_url":"https://github.com/pycaret/pycaret/issues/117","id":615127138,"node_id":"MDU6SXNzdWU2MTUxMjcxMzg=","number":117,"title":"typeError: can only concatenate str (not \"float\") to str","user":{"login":"eliwchen","id":55618789,"node_id":"MDQ6VXNlcjU1NjE4Nzg5","avatar_url":"https://avatars1.githubusercontent.com/u/55618789?v=4","gravatar_id":"","url":"https://api.github.com/users/eliwchen","html_url":"https://github.com/eliwchen","followers_url":"https://api.github.com/users/eliwchen/followers","following_url":"https://api.github.com/users/eliwchen/following{/other_user}","gists_url":"https://api.github.com/users/eliwchen/gists{/gist_id}","starred_url":"https://api.github.com/users/eliwchen/starred{/owner}{/repo}","subscriptions_url":"https://api.github.com/users/eliwchen/subscriptions","organizations_url":"https://api.github.com/users/eliwchen/orgs","repos_url":"https://api.github.com/users/eliwchen/repos","events_url":"https://api.github.com/users/eliwchen/events{/privacy}","received_events_url":"https://api.github.com/users/eliwchen/received_events","type":"User","site_admin":false},"labels":[{"id":1694165746,"node_id":"MDU6TGFiZWwxNjk0MTY1NzQ2","url":"https://api.github.com/repos/pycaret/pycaret/labels/bug","name":"bug","color":"d73a4a","default":true,"description":"Something isn't working"}],"state":"closed","locked":false,"assignee":null,"assignees":[],"milestone":null,"comments":2,"created_at":"2020-05-09T08:50:48Z","updated_at":"2020-07-30T22:32:16Z","closed_at":"2020-07-30T22:32:16Z","author_association":"NONE","active_lock_reason":null,"body":"I get the typeError, when I  import a  dataset.\r\nThe detail is below.\r\n\r\nTypeError                                 Traceback (most recent call last)\r\n<ipython-input-25-819900f202da> in <module>\r\n----> 1 s= setup(data,target=\"price\",categorical_features=cat_feat)\r\n\r\n~\\AppData\\Roaming\\Python\\Python37\\site-packages\\pycaret\\regression.py in setup(data, target, train_size, sampling, sample_estimator, categorical_features, categorical_imputation, ordinal_features, high_cardinality_features, high_cardinality_method, numeric_features, numeric_imputation, date_features, ignore_features, normalize, normalize_method, transformation, transformation_method, handle_unknown_categorical, unknown_categorical_method, pca, pca_method, pca_components, ignore_low_variance, combine_rare_levels, rare_level_threshold, bin_numeric_features, remove_outliers, outliers_threshold, remove_multicollinearity, multicollinearity_threshold, create_clusters, cluster_iter, polynomial_features, polynomial_degree, trigonometry_features, polynomial_threshold, group_features, group_names, feature_selection, feature_selection_threshold, feature_interaction, feature_ratio, interaction_threshold, transform_target, transform_target_method, session_id, silent, profile)\r\n    955                                           target_transformation = transform_target, #new\r\n    956                                           target_transformation_method = transform_target_method_pass, #new\r\n--> 957                                           random_state = seed)\r\n    958 \r\n    959     progress.value += 1\r\n\r\n~\\AppData\\Roaming\\Python\\Python37\\site-packages\\pycaret\\preprocess.py in Preprocess_Path_One(train_data, target_variable, ml_usecase, test_data, categorical_features, numerical_features, time_features, features_todrop, display_types, imputation_type, numeric_imputation_strategy, categorical_imputation_strategy, apply_zero_nearZero_variance, club_rare_levels, rara_level_threshold_percentage, apply_untrained_levels_treatment, untrained_levels_treatment_method, apply_ordinal_encoding, ordinal_columns_and_categories, apply_cardinality_reduction, cardinal_method, cardinal_features, apply_binning, features_to_binn, apply_grouping, group_name, features_to_group_ListofList, apply_polynomial_trigonometry_features, max_polynomial, trigonometry_calculations, top_poly_trig_features_to_select_percentage, scale_data, scaling_method, Power_transform_data, Power_transform_method, target_transformation, target_transformation_method, remove_outliers, outlier_contamination_percentage, outlier_methods, apply_feature_selection, feature_selection_top_features_percentage, remove_multicollinearity, maximum_correlation_between_features, remove_perfect_collinearity, apply_feature_interactions, feature_interactions_to_apply, feature_interactions_top_features_to_select_percentage, cluster_entire_data, range_of_clusters_to_try, apply_pca, pca_method, pca_variance_retained_or_number_of_components, random_state)\r\n   2538     return(pipe.fit_transform(train_data),pipe.transform(test_data))\r\n   2539   else:\r\n-> 2540     return(pipe.fit_transform(train_data))\r\n   2541 \r\n   2542 \r\n\r\nE:\\ProgramData\\Anaconda3\\lib\\site-packages\\sklearn\\pipeline.py in fit_transform(self, X, y, **fit_params)\r\n    381         \"\"\"\r\n    382         last_step = self._final_estimator\r\n--> 383         Xt, fit_params = self._fit(X, y, **fit_params)\r\n    384         with _print_elapsed_time('Pipeline',\r\n    385                                  self._log_message(len(self.steps) - 1)):\r\n\r\nE:\\ProgramData\\Anaconda3\\lib\\site-packages\\sklearn\\pipeline.py in _fit(self, X, y, **fit_params)\r\n    311                 message_clsname='Pipeline',\r\n    312                 message=self._log_message(step_idx),\r\n--> 313                 **fit_params_steps[name])\r\n    314             # Replace the transformer of the step with the fitted\r\n    315             # transformer. This is necessary when loading the transformer\r\n\r\nE:\\ProgramData\\Anaconda3\\lib\\site-packages\\joblib\\memory.py in __call__(self, *args, **kwargs)\r\n    353 \r\n    354     def __call__(self, *args, **kwargs):\r\n--> 355         return self.func(*args, **kwargs)\r\n    356 \r\n    357     def call_and_shelve(self, *args, **kwargs):\r\n\r\nE:\\ProgramData\\Anaconda3\\lib\\site-packages\\sklearn\\pipeline.py in _fit_transform_one(transformer, X, y, weight, message_clsname, message, **fit_params)\r\n    724     with _print_elapsed_time(message_clsname, message):\r\n    725         if hasattr(transformer, 'fit_transform'):\r\n--> 726             res = transformer.fit_transform(X, y, **fit_params)\r\n    727         else:\r\n    728             res = transformer.fit(X, y, **fit_params).transform(X)\r\n\r\n~\\AppData\\Roaming\\Python\\Python37\\site-packages\\pycaret\\preprocess.py in fit_transform(self, dataset, y)\r\n   1957   def fit_transform(self,dataset,y=None):\r\n   1958     data = dataset.copy()\r\n-> 1959     corr = pd.DataFrame(np.corrcoef(data.drop(self.target,axis=1).T))\r\n   1960     corr.columns = data.drop(self.target,axis=1).columns\r\n   1961     corr.index = data.drop(self.target,axis=1).columns\r\n\r\n<__array_function__ internals> in corrcoef(*args, **kwargs)\r\n\r\nE:\\ProgramData\\Anaconda3\\lib\\site-packages\\numpy\\lib\\function_base.py in corrcoef(x, y, rowvar, bias, ddof)\r\n   2524         warnings.warn('bias and ddof have no effect and are deprecated',\r\n   2525                       DeprecationWarning, stacklevel=3)\r\n-> 2526     c = cov(x, y, rowvar)\r\n   2527     try:\r\n   2528         d = diag(c)\r\n\r\n<__array_function__ internals> in cov(*args, **kwargs)\r\n\r\nE:\\ProgramData\\Anaconda3\\lib\\site-packages\\numpy\\lib\\function_base.py in cov(m, y, rowvar, bias, ddof, fweights, aweights)\r\n   2429             w *= aweights\r\n   2430 \r\n-> 2431     avg, w_sum = average(X, axis=1, weights=w, returned=True)\r\n   2432     w_sum = w_sum[0]\r\n   2433 \r\n\r\n<__array_function__ internals> in average(*args, **kwargs)\r\n\r\nE:\\ProgramData\\Anaconda3\\lib\\site-packages\\numpy\\lib\\function_base.py in average(a, axis, weights, returned)\r\n    391 \r\n    392     if weights is None:\r\n--> 393         avg = a.mean(axis)\r\n    394         scl = avg.dtype.type(a.size/avg.size)\r\n    395     else:\r\n\r\nE:\\ProgramData\\Anaconda3\\lib\\site-packages\\numpy\\core\\_methods.py in _mean(a, axis, dtype, out, keepdims)\r\n    149             is_float16_result = True\r\n    150 \r\n--> 151     ret = umr_sum(arr, axis, dtype, out, keepdims)\r\n    152     if isinstance(ret, mu.ndarray):\r\n    153         ret = um.true_divide(\r\n\r\nTypeError: can only concatenate str (not \"float\") to str","performed_via_github_app":null},{"url":"https://api.github.com/repos/pycaret/pycaret/issues/102","repository_url":"https://api.github.com/repos/pycaret/pycaret","labels_url":"https://api.github.com/repos/pycaret/pycaret/issues/102/labels{/name}","comments_url":"https://api.github.com/repos/pycaret/pycaret/issues/102/comments","events_url":"https://api.github.com/repos/pycaret/pycaret/issues/102/events","html_url":"https://github.com/pycaret/pycaret/issues/102","id":611759399,"node_id":"MDU6SXNzdWU2MTE3NTkzOTk=","number":102,"title":"OverflowError: cannot convert float infinity to integer","user":{"login":"skwolvie","id":22741452,"node_id":"MDQ6VXNlcjIyNzQxNDUy","avatar_url":"https://avatars1.githubusercontent.com/u/22741452?v=4","gravatar_id":"","url":"https://api.github.com/users/skwolvie","html_url":"https://github.com/skwolvie","followers_url":"https://api.github.com/users/skwolvie/followers","following_url":"https://api.github.com/users/skwolvie/following{/other_user}","gists_url":"https://api.github.com/users/skwolvie/gists{/gist_id}","starred_url":"https://api.github.com/users/skwolvie/starred{/owner}{/repo}","subscriptions_url":"https://api.github.com/users/skwolvie/subscriptions","organizations_url":"https://api.github.com/users/skwolvie/orgs","repos_url":"https://api.github.com/users/skwolvie/repos","events_url":"https://api.github.com/users/skwolvie/events{/privacy}","received_events_url":"https://api.github.com/users/skwolvie/received_events","type":"User","site_admin":false},"labels":[{"id":1694165746,"node_id":"MDU6TGFiZWwxNjk0MTY1NzQ2","url":"https://api.github.com/repos/pycaret/pycaret/labels/bug","name":"bug","color":"d73a4a","default":true,"description":"Something isn't working"}],"state":"closed","locked":false,"assignee":null,"assignees":[],"milestone":null,"comments":5,"created_at":"2020-05-04T10:14:59Z","updated_at":"2020-07-30T22:31:58Z","closed_at":"2020-07-30T22:31:58Z","author_association":"NONE","active_lock_reason":null,"body":"![image](https://user-images.githubusercontent.com/22741452/80956103-276f7380-8e1e-11ea-949f-3eec575ae0c4.png)\r\n\r\n![image](https://user-images.githubusercontent.com/22741452/80956129-33f3cc00-8e1e-11ea-8f02-053c0578c484.png)\r\n","performed_via_github_app":null},{"url":"https://api.github.com/repos/pycaret/pycaret/issues/96","repository_url":"https://api.github.com/repos/pycaret/pycaret","labels_url":"https://api.github.com/repos/pycaret/pycaret/issues/96/labels{/name}","comments_url":"https://api.github.com/repos/pycaret/pycaret/issues/96/comments","events_url":"https://api.github.com/repos/pycaret/pycaret/issues/96/events","html_url":"https://github.com/pycaret/pycaret/issues/96","id":611090220,"node_id":"MDU6SXNzdWU2MTEwOTAyMjA=","number":96,"title":"PyCaret is unable to scale for large datasets","user":{"login":"sid-the-coder","id":56773306,"node_id":"MDQ6VXNlcjU2NzczMzA2","avatar_url":"https://avatars1.githubusercontent.com/u/56773306?v=4","gravatar_id":"","url":"https://api.github.com/users/sid-the-coder","html_url":"https://github.com/sid-the-coder","followers_url":"https://api.github.com/users/sid-the-coder/followers","following_url":"https://api.github.com/users/sid-the-coder/following{/other_user}","gists_url":"https://api.github.com/users/sid-the-coder/gists{/gist_id}","starred_url":"https://api.github.com/users/sid-the-coder/starred{/owner}{/repo}","subscriptions_url":"https://api.github.com/users/sid-the-coder/subscriptions","organizations_url":"https://api.github.com/users/sid-the-coder/orgs","repos_url":"https://api.github.com/users/sid-the-coder/repos","events_url":"https://api.github.com/users/sid-the-coder/events{/privacy}","received_events_url":"https://api.github.com/users/sid-the-coder/received_events","type":"User","site_admin":false},"labels":[{"id":1694165746,"node_id":"MDU6TGFiZWwxNjk0MTY1NzQ2","url":"https://api.github.com/repos/pycaret/pycaret/labels/bug","name":"bug","color":"d73a4a","default":true,"description":"Something isn't working"}],"state":"closed","locked":false,"assignee":null,"assignees":[],"milestone":null,"comments":4,"created_at":"2020-05-02T02:30:26Z","updated_at":"2020-09-02T03:30:59Z","closed_at":"2020-07-30T22:05:50Z","author_association":"NONE","active_lock_reason":null,"body":"I'm facing some issue with the setup() while using this dataset which contains 4357336 rows and 26 columns. \r\n\r\nHere's the Kaggle link:\r\nhttps://www.kaggle.com/c/pubg-finish-placement-prediction/data\r\n\r\nI tried to run my scripts on Google Colab using GPU/TPU but I am facing similar issues. It crashes after confirming the feature types. \r\n\r\nIs this supposed to happen for large datasets. If yes, how do I rectify it?\r\n\r\nP.S. Thank you for this awesome library! I love using it!","performed_via_github_app":null},{"url":"https://api.github.com/repos/pycaret/pycaret/issues/58","repository_url":"https://api.github.com/repos/pycaret/pycaret","labels_url":"https://api.github.com/repos/pycaret/pycaret/issues/58/labels{/name}","comments_url":"https://api.github.com/repos/pycaret/pycaret/issues/58/comments","events_url":"https://api.github.com/repos/pycaret/pycaret/issues/58/events","html_url":"https://github.com/pycaret/pycaret/issues/58","id":607032654,"node_id":"MDU6SXNzdWU2MDcwMzI2NTQ=","number":58,"title":"Set n_jobs","user":{"login":"reza1615","id":2202483,"node_id":"MDQ6VXNlcjIyMDI0ODM=","avatar_url":"https://avatars0.githubusercontent.com/u/2202483?v=4","gravatar_id":"","url":"https://api.github.com/users/reza1615","html_url":"https://github.com/reza1615","followers_url":"https://api.github.com/users/reza1615/followers","following_url":"https://api.github.com/users/reza1615/following{/other_user}","gists_url":"https://api.github.com/users/reza1615/gists{/gist_id}","starred_url":"https://api.github.com/users/reza1615/starred{/owner}{/repo}","subscriptions_url":"https://api.github.com/users/reza1615/subscriptions","organizations_url":"https://api.github.com/users/reza1615/orgs","repos_url":"https://api.github.com/users/reza1615/repos","events_url":"https://api.github.com/users/reza1615/events{/privacy}","received_events_url":"https://api.github.com/users/reza1615/received_events","type":"User","site_admin":false},"labels":[{"id":1694165746,"node_id":"MDU6TGFiZWwxNjk0MTY1NzQ2","url":"https://api.github.com/repos/pycaret/pycaret/labels/bug","name":"bug","color":"d73a4a","default":true,"description":"Something isn't working"}],"state":"closed","locked":false,"assignee":null,"assignees":[],"milestone":null,"comments":4,"created_at":"2020-04-26T14:59:51Z","updated_at":"2020-04-28T21:56:59Z","closed_at":"2020-04-28T21:56:59Z","author_association":"CONTRIBUTOR","active_lock_reason":null,"body":"How can i set n_jobs=-1","performed_via_github_app":null},{"url":"https://api.github.com/repos/pycaret/pycaret/issues/56","repository_url":"https://api.github.com/repos/pycaret/pycaret","labels_url":"https://api.github.com/repos/pycaret/pycaret/issues/56/labels{/name}","comments_url":"https://api.github.com/repos/pycaret/pycaret/issues/56/comments","events_url":"https://api.github.com/repos/pycaret/pycaret/issues/56/events","html_url":"https://github.com/pycaret/pycaret/issues/56","id":607014265,"node_id":"MDU6SXNzdWU2MDcwMTQyNjU=","number":56,"title":"Showing warning message instead of error","user":{"login":"reza1615","id":2202483,"node_id":"MDQ6VXNlcjIyMDI0ODM=","avatar_url":"https://avatars0.githubusercontent.com/u/2202483?v=4","gravatar_id":"","url":"https://api.github.com/users/reza1615","html_url":"https://github.com/reza1615","followers_url":"https://api.github.com/users/reza1615/followers","following_url":"https://api.github.com/users/reza1615/following{/other_user}","gists_url":"https://api.github.com/users/reza1615/gists{/gist_id}","starred_url":"https://api.github.com/users/reza1615/starred{/owner}{/repo}","subscriptions_url":"https://api.github.com/users/reza1615/subscriptions","organizations_url":"https://api.github.com/users/reza1615/orgs","repos_url":"https://api.github.com/users/reza1615/repos","events_url":"https://api.github.com/users/reza1615/events{/privacy}","received_events_url":"https://api.github.com/users/reza1615/received_events","type":"User","site_admin":false},"labels":[{"id":1694165746,"node_id":"MDU6TGFiZWwxNjk0MTY1NzQ2","url":"https://api.github.com/repos/pycaret/pycaret/labels/bug","name":"bug","color":"d73a4a","default":true,"description":"Something isn't working"},{"id":1694165753,"node_id":"MDU6TGFiZWwxNjk0MTY1NzUz","url":"https://api.github.com/repos/pycaret/pycaret/labels/enhancement","name":"enhancement","color":"a2eeef","default":true,"description":"New feature or request"}],"state":"closed","locked":false,"assignee":null,"assignees":[],"milestone":null,"comments":2,"created_at":"2020-04-26T13:36:03Z","updated_at":"2020-05-06T11:09:15Z","closed_at":"2020-05-06T11:09:15Z","author_association":"CONTRIBUTOR","active_lock_reason":null,"body":"It would be perfect to inactive buttons for multi-class classification or showing a warning message instead of error.\r\n![image](https://user-images.githubusercontent.com/2202483/80309149-116c0e00-87a1-11ea-9e51-3a21976682ad.png)\r\n","performed_via_github_app":null},{"url":"https://api.github.com/repos/pycaret/pycaret/issues/30","repository_url":"https://api.github.com/repos/pycaret/pycaret","labels_url":"https://api.github.com/repos/pycaret/pycaret/issues/30/labels{/name}","comments_url":"https://api.github.com/repos/pycaret/pycaret/issues/30/comments","events_url":"https://api.github.com/repos/pycaret/pycaret/issues/30/events","html_url":"https://github.com/pycaret/pycaret/issues/30","id":604169561,"node_id":"MDU6SXNzdWU2MDQxNjk1NjE=","number":30,"title":"compare model bugg","user":{"login":"mfahadakbar","id":19522276,"node_id":"MDQ6VXNlcjE5NTIyMjc2","avatar_url":"https://avatars0.githubusercontent.com/u/19522276?v=4","gravatar_id":"","url":"https://api.github.com/users/mfahadakbar","html_url":"https://github.com/mfahadakbar","followers_url":"https://api.github.com/users/mfahadakbar/followers","following_url":"https://api.github.com/users/mfahadakbar/following{/other_user}","gists_url":"https://api.github.com/users/mfahadakbar/gists{/gist_id}","starred_url":"https://api.github.com/users/mfahadakbar/starred{/owner}{/repo}","subscriptions_url":"https://api.github.com/users/mfahadakbar/subscriptions","organizations_url":"https://api.github.com/users/mfahadakbar/orgs","repos_url":"https://api.github.com/users/mfahadakbar/repos","events_url":"https://api.github.com/users/mfahadakbar/events{/privacy}","received_events_url":"https://api.github.com/users/mfahadakbar/received_events","type":"User","site_admin":false},"labels":[{"id":1694165746,"node_id":"MDU6TGFiZWwxNjk0MTY1NzQ2","url":"https://api.github.com/repos/pycaret/pycaret/labels/bug","name":"bug","color":"d73a4a","default":true,"description":"Something isn't working"}],"state":"closed","locked":false,"assignee":null,"assignees":[],"milestone":null,"comments":1,"created_at":"2020-04-21T17:48:58Z","updated_at":"2020-07-06T17:06:33Z","closed_at":"2020-07-06T17:06:33Z","author_association":"CONTRIBUTOR","active_lock_reason":null,"body":"compare mode failing here :\r\n![Capture](https://user-images.githubusercontent.com/19522276/79896776-c5068400-83d6-11ea-9309-51035cc29760.PNG)\r\n","performed_via_github_app":null},{"url":"https://api.github.com/repos/pycaret/pycaret/issues/24","repository_url":"https://api.github.com/repos/pycaret/pycaret","labels_url":"https://api.github.com/repos/pycaret/pycaret/issues/24/labels{/name}","comments_url":"https://api.github.com/repos/pycaret/pycaret/issues/24/comments","events_url":"https://api.github.com/repos/pycaret/pycaret/issues/24/events","html_url":"https://github.com/pycaret/pycaret/issues/24","id":602538489,"node_id":"MDU6SXNzdWU2MDI1Mzg0ODk=","number":24,"title":"int32 issue","user":{"login":"ajayprakashm","id":54311907,"node_id":"MDQ6VXNlcjU0MzExOTA3","avatar_url":"https://avatars3.githubusercontent.com/u/54311907?v=4","gravatar_id":"","url":"https://api.github.com/users/ajayprakashm","html_url":"https://github.com/ajayprakashm","followers_url":"https://api.github.com/users/ajayprakashm/followers","following_url":"https://api.github.com/users/ajayprakashm/following{/other_user}","gists_url":"https://api.github.com/users/ajayprakashm/gists{/gist_id}","starred_url":"https://api.github.com/users/ajayprakashm/starred{/owner}{/repo}","subscriptions_url":"https://api.github.com/users/ajayprakashm/subscriptions","organizations_url":"https://api.github.com/users/ajayprakashm/orgs","repos_url":"https://api.github.com/users/ajayprakashm/repos","events_url":"https://api.github.com/users/ajayprakashm/events{/privacy}","received_events_url":"https://api.github.com/users/ajayprakashm/received_events","type":"User","site_admin":false},"labels":[{"id":1694165746,"node_id":"MDU6TGFiZWwxNjk0MTY1NzQ2","url":"https://api.github.com/repos/pycaret/pycaret/labels/bug","name":"bug","color":"d73a4a","default":true,"description":"Something isn't working"}],"state":"closed","locked":false,"assignee":null,"assignees":[],"milestone":null,"comments":3,"created_at":"2020-04-18T19:53:29Z","updated_at":"2020-07-30T19:20:17Z","closed_at":"2020-07-30T19:20:17Z","author_association":"NONE","active_lock_reason":null,"body":"Hi,\r\nI tried to use the package for classification problem, and when i entered the dataframe with target data in setup environment and ran the code, it showed no dtype for the dataframe, but it has dtype of 'int32'. When i changed the dtype to int64, it worked. Can you fix this issue.","performed_via_github_app":null},{"url":"https://api.github.com/repos/pycaret/pycaret/issues/19","repository_url":"https://api.github.com/repos/pycaret/pycaret","labels_url":"https://api.github.com/repos/pycaret/pycaret/issues/19/labels{/name}","comments_url":"https://api.github.com/repos/pycaret/pycaret/issues/19/comments","events_url":"https://api.github.com/repos/pycaret/pycaret/issues/19/events","html_url":"https://github.com/pycaret/pycaret/issues/19","id":602465657,"node_id":"MDU6SXNzdWU2MDI0NjU2NTc=","number":19,"title":"Memmory related Crash","user":{"login":"npapan69","id":39875077,"node_id":"MDQ6VXNlcjM5ODc1MDc3","avatar_url":"https://avatars0.githubusercontent.com/u/39875077?v=4","gravatar_id":"","url":"https://api.github.com/users/npapan69","html_url":"https://github.com/npapan69","followers_url":"https://api.github.com/users/npapan69/followers","following_url":"https://api.github.com/users/npapan69/following{/other_user}","gists_url":"https://api.github.com/users/npapan69/gists{/gist_id}","starred_url":"https://api.github.com/users/npapan69/starred{/owner}{/repo}","subscriptions_url":"https://api.github.com/users/npapan69/subscriptions","organizations_url":"https://api.github.com/users/npapan69/orgs","repos_url":"https://api.github.com/users/npapan69/repos","events_url":"https://api.github.com/users/npapan69/events{/privacy}","received_events_url":"https://api.github.com/users/npapan69/received_events","type":"User","site_admin":false},"labels":[{"id":1694165746,"node_id":"MDU6TGFiZWwxNjk0MTY1NzQ2","url":"https://api.github.com/repos/pycaret/pycaret/labels/bug","name":"bug","color":"d73a4a","default":true,"description":"Something isn't working"}],"state":"closed","locked":false,"assignee":null,"assignees":[],"milestone":null,"comments":11,"created_at":"2020-04-18T13:55:38Z","updated_at":"2020-04-29T17:53:20Z","closed_at":"2020-04-29T17:53:20Z","author_association":"NONE","active_lock_reason":null,"body":"Dear All,\r\n\r\nThanks for the great library, I'm facing problems when trying to use pandas to import my csv which has 130 rows and 110 columns. It consumes all my RAM (which is 64GB, MacBook Pro 16\") and crashes. Any ideas? Up till now, I was able to use it only with csv files with a limited number of columns .\r\n\r\nNikos","performed_via_github_app":null},{"url":"https://api.github.com/repos/pycaret/pycaret/issues/18","repository_url":"https://api.github.com/repos/pycaret/pycaret","labels_url":"https://api.github.com/repos/pycaret/pycaret/issues/18/labels{/name}","comments_url":"https://api.github.com/repos/pycaret/pycaret/issues/18/comments","events_url":"https://api.github.com/repos/pycaret/pycaret/issues/18/events","html_url":"https://github.com/pycaret/pycaret/issues/18","id":602407836,"node_id":"MDU6SXNzdWU2MDI0MDc4MzY=","number":18,"title":"Dataframe constructor not properly called","user":{"login":"BismeetSingh","id":13601266,"node_id":"MDQ6VXNlcjEzNjAxMjY2","avatar_url":"https://avatars3.githubusercontent.com/u/13601266?v=4","gravatar_id":"","url":"https://api.github.com/users/BismeetSingh","html_url":"https://github.com/BismeetSingh","followers_url":"https://api.github.com/users/BismeetSingh/followers","following_url":"https://api.github.com/users/BismeetSingh/following{/other_user}","gists_url":"https://api.github.com/users/BismeetSingh/gists{/gist_id}","starred_url":"https://api.github.com/users/BismeetSingh/starred{/owner}{/repo}","subscriptions_url":"https://api.github.com/users/BismeetSingh/subscriptions","organizations_url":"https://api.github.com/users/BismeetSingh/orgs","repos_url":"https://api.github.com/users/BismeetSingh/repos","events_url":"https://api.github.com/users/BismeetSingh/events{/privacy}","received_events_url":"https://api.github.com/users/BismeetSingh/received_events","type":"User","site_admin":false},"labels":[{"id":1694165746,"node_id":"MDU6TGFiZWwxNjk0MTY1NzQ2","url":"https://api.github.com/repos/pycaret/pycaret/labels/bug","name":"bug","color":"d73a4a","default":true,"description":"Something isn't working"}],"state":"closed","locked":false,"assignee":null,"assignees":[],"milestone":null,"comments":9,"created_at":"2020-04-18T08:23:50Z","updated_at":"2020-07-06T17:04:00Z","closed_at":"2020-07-06T17:03:59Z","author_association":"NONE","active_lock_reason":null,"body":"While running a simple linear regression model on kaggle using pycaret, I get the error \r\nDataFrame constructor not properly called on running setup. The dataset contains only two columns.\r\n\r\n```\r\ndf=pd.read_csv(\"/kaggle/input/salary-data-simple-linear-regression/Salary_Data.csv\")`\r\nsetup_data1 = setup(data = df, target = 'Salary', session_id=123) \r\n```\r\nLogs:\r\n---------------------------------------------------------------------------\r\nValueError                                Traceback (most recent call last)\r\n<ipython-input-12-c3ad091d442b> in <module>\r\n----> 1 setup_data1 = setup(data = df, target = 'Salary', session_id=123)\r\n\r\n/opt/conda/lib/python3.6/site-packages/pycaret/regression.py in setup(data, target, train_size, sampling, sample_estimator, categorical_features, categorical_imputation, ordinal_features, high_cardinality_features, high_cardinality_method, numeric_features, numeric_imputation, date_features, ignore_features, normalize, normalize_method, transformation, transformation_method, handle_unknown_categorical, unknown_categorical_method, pca, pca_method, pca_components, ignore_low_variance, combine_rare_levels, rare_level_threshold, bin_numeric_features, remove_outliers, outliers_threshold, remove_multicollinearity, multicollinearity_threshold, create_clusters, cluster_iter, polynomial_features, polynomial_degree, trigonometry_features, polynomial_threshold, group_features, group_names, feature_selection, feature_selection_threshold, feature_interaction, feature_ratio, interaction_threshold, transform_target, transform_target_method, session_id, silent, profile)\r\n    955                                           target_transformation = transform_target, #new\r\n    956                                           target_transformation_method = transform_target_method_pass, #new\r\n--> 957                                           random_state = seed)\r\n    958 \r\n    959     progress.value += 1\r\n\r\n/opt/conda/lib/python3.6/site-packages/pycaret/preprocess.py in Preprocess_Path_One(train_data, target_variable, ml_usecase, test_data, categorical_features, numerical_features, time_features, features_todrop, display_types, imputation_type, numeric_imputation_strategy, categorical_imputation_strategy, apply_zero_nearZero_variance, club_rare_levels, rara_level_threshold_percentage, apply_untrained_levels_treatment, untrained_levels_treatment_method, apply_ordinal_encoding, ordinal_columns_and_categories, apply_cardinality_reduction, cardinal_method, cardinal_features, apply_binning, features_to_binn, apply_grouping, group_name, features_to_group_ListofList, apply_polynomial_trigonometry_features, max_polynomial, trigonometry_calculations, top_poly_trig_features_to_select_percentage, scale_data, scaling_method, Power_transform_data, Power_transform_method, target_transformation, target_transformation_method, remove_outliers, outlier_contamination_percentage, outlier_methods, apply_feature_selection, feature_selection_top_features_percentage, remove_multicollinearity, maximum_correlation_between_features, remove_perfect_collinearity, apply_feature_interactions, feature_interactions_to_apply, feature_interactions_top_features_to_select_percentage, cluster_entire_data, range_of_clusters_to_try, apply_pca, pca_method, pca_variance_retained_or_number_of_components, random_state)\r\n   2538     return(pipe.fit_transform(train_data),pipe.transform(test_data))\r\n   2539   else:\r\n-> 2540     return(pipe.fit_transform(train_data))\r\n   2541 \r\n   2542 \r\n\r\n/opt/conda/lib/python3.6/site-packages/sklearn/pipeline.py in fit_transform(self, X, y, **fit_params)\r\n    381         \"\"\"\r\n    382         last_step = self._final_estimator\r\n--> 383         Xt, fit_params = self._fit(X, y, **fit_params)\r\n    384         with _print_elapsed_time('Pipeline',\r\n    385                                  self._log_message(len(self.steps) - 1)):\r\n\r\n/opt/conda/lib/python3.6/site-packages/sklearn/pipeline.py in _fit(self, X, y, **fit_params)\r\n    311                 message_clsname='Pipeline',\r\n    312                 message=self._log_message(step_idx),\r\n--> 313                 **fit_params_steps[name])\r\n    314             # Replace the transformer of the step with the fitted\r\n    315             # transformer. This is necessary when loading the transformer\r\n\r\n/opt/conda/lib/python3.6/site-packages/joblib/memory.py in __call__(self, *args, **kwargs)\r\n    353 \r\n    354     def __call__(self, *args, **kwargs):\r\n--> 355         return self.func(*args, **kwargs)\r\n    356 \r\n    357     def call_and_shelve(self, *args, **kwargs):\r\n\r\n/opt/conda/lib/python3.6/site-packages/sklearn/pipeline.py in _fit_transform_one(transformer, X, y, weight, message_clsname, message, **fit_params)\r\n    724     with _print_elapsed_time(message_clsname, message):\r\n    725         if hasattr(transformer, 'fit_transform'):\r\n--> 726             res = transformer.fit_transform(X, y, **fit_params)\r\n    727         else:\r\n    728             res = transformer.fit(X, y, **fit_params).transform(X)\r\n\r\n/opt/conda/lib/python3.6/site-packages/pycaret/preprocess.py in fit_transform(self, dataset, y)\r\n   1957   def fit_transform(self,dataset,y=None):\r\n   1958     data = dataset.copy()\r\n-> 1959     corr = pd.DataFrame(np.corrcoef(data.drop(self.target,axis=1).T))\r\n   1960     corr.columns = data.drop(self.target,axis=1).columns\r\n   1961     corr.index = data.drop(self.target,axis=1).columns\r\n\r\n/opt/conda/lib/python3.6/site-packages/pandas/core/frame.py in __init__(self, data, index, columns, dtype, copy)\r\n    483                 )\r\n    484             else:\r\n--> 485                 raise ValueError(\"DataFrame constructor not properly called!\")\r\n    486 \r\n    487         NDFrame.__init__(self, mgr, fastpath=True)\r\n\r\nValueError: DataFrame constructor not properly called!\r\n\r\n","performed_via_github_app":null}]